<?xml version="1.0" encoding="utf-8"?>
<robot name="yahboomcar" xmlns:xacro="http://www.ros.org/wiki/xacro">
    <!-- <xacro:include filename="package://x3_description/urdf/yahboomcar_X3.gazebo.xacro"/> -->
    <material name="Green">
        <color rgba="0 0.7 0 1"/>
    </material>
    <material name="White">
        <color rgba="0.7 0.7 0.7 1"/>
    </material>
    
    <link name="base_footprint"/>
    <link name="imu_link"/>
    <link name="base_link">
        <inertial>
            <origin xyz="0.00498197982182523 5.70233829969297E-05 -0.0121008098068578" rpy="0 0 0"/>
            <mass value="0.486218814966626"/>
            <inertia
                    ixx="0.00196277727666921"
                    ixy="2.50447049446755E-07"
                    ixz="0.000140534767811098"
                    iyy="0.00457256033711368"
                    iyz="2.68618064993882E-07"
                    izz="0.00493927269870476"/>
        </inertial>
        <visual>
            <origin xyz="0 0 0" rpy="0 0 0"/>
            <geometry>
                <mesh filename="file://$(find x3_description)/meshes/mecanum/base_link_X3.STL"/>
            </geometry>
            <material name="green">
                <color rgba="0 0.7 0 1"/>
            </material>
        </visual>
        <collision>
            <origin xyz="0 0 0" rpy="0 0 0"/>
            <geometry>
                <mesh filename="file://$(find x3_description)/meshes/mecanum/base_link_X3.STL"/>
            </geometry>
        </collision>
    </link>
    <joint name="base_joint" type="fixed">
        <parent link="base_footprint"/>
        <child link="base_link"/>
        <origin xyz="0.0 0.0 0.0815" rpy="0 0 0"/>
    </joint>
    <joint name="base_imu" type="fixed">
        <parent link="base_link"/>
        <child link="imu_link"/>
        <origin xyz="-0.06 0.01 0.01" rpy="0 3.1415 1.5707"/>
    </joint>
    <link name="front_right_wheel">
        <inertial>
            <origin xyz="0.08 -0.0845 -0.0389" rpy="0 0 0"/>
            <mass value="0.05"/>
            <inertia ixx="1.25E-03" ixy="0" ixz="0"
                    iyy="1.25E-03" iyz="0" izz="1.0E-05"/>
        </inertial>
        <visual>
            <origin xyz="0 0 0" rpy="0 0 0"/>
            <geometry>
                <mesh filename="file://$(find x3_description)/meshes/mecanum/front_right_wheel_X3.STL"/>
            </geometry>
            <material name="">
                <color rgba="0.7 0.7 0.7 1"/>
            </material>
        </visual>
        <collision>
            <origin xyz="0 0 0" rpy="0 0 0"/>
            <geometry>
                <mesh filename="file://$(find x3_description)/meshes/mecanum/front_right_wheel_X3.STL"/>
            </geometry>
        </collision>
    </link>
    <joint name="front_right_joint" type="continuous">
        <origin xyz="0.08 -0.0845 -0.0389" rpy="-1.5703 0 3.14159"/>
        <parent link="base_link"/>
        <child link="front_right_wheel"/>
        <axis xyz="0 0 1" rpy="0 0 0"/>
        <limit effort="100" velocity="1"/>
    </joint>

    <link name="front_left_wheel">
        <inertial>
            <origin xyz="0.08 0.0845 -0.0389" rpy="0 0 0"/>
            <mass value="0.05"/>
            <inertia ixx="1.25E-03" ixy="0" ixz="0"
                    iyy="1.25E-03" iyz="0" izz="1.0E-05"/>
        </inertial>
        <visual>
            <origin xyz="0 0 0" rpy="0 0 0"/>
            <geometry>
                <mesh filename="file://$(find x3_description)/meshes/mecanum/front_left_wheel_X3.STL"/>
            </geometry>
            <material name="">
                <color rgba="0.7 0.7 0.7 1"/>
            </material>
        </visual>
        <collision>
            <origin xyz="0 0 0" rpy="0 0 0"/>
            <geometry>
                <mesh filename="file://$(find x3_description)/meshes/mecanum/front_left_wheel_X3.STL"/>
            </geometry>
        </collision>
    </link>
    <joint name="front_left_joint" type="continuous">
        <origin xyz="0.08 0.0845 -0.0389" rpy="1.5703 0 0"/>
        <parent link="base_link"/>
        <child link="front_left_wheel"/>
        <axis xyz="0 0 1" rpy="0 0 0"/>
        <limit effort="100" velocity="1"/>
    </joint>

    <link name="back_right_wheel">
        <inertial>
            <origin xyz="-0.08 -0.0845 -0.0389" rpy="0 0 0"/>
            <mass value="0.05"/>
            <inertia ixx="1.25E-03" ixy="0" ixz="0"
                    iyy="1.25E-03" iyz="0" izz="1.0E-05"/>
        </inertial>
        <visual>
            <origin xyz="0 0 0" rpy="0 0 0"/>
            <geometry>
                <mesh filename="file://$(find x3_description)/meshes/mecanum/back_right_wheel_X3.STL"/>
            </geometry>
            <material name="">
                <color rgba="0.7 0.7 0.7 1"/>
            </material>
        </visual>
        <collision>
            <origin xyz="0 0 0" rpy="0 0 0"/>
            <geometry>
                <mesh filename="file://$(find x3_description)/meshes/mecanum/back_right_wheel_X3.STL"/>
            </geometry>
        </collision>
    </link>
    <joint name="back_right_joint" type="continuous">
        <origin xyz="-0.08 -0.0845 -0.0389" rpy="-1.57 0 3.14159"/>
        <parent link="base_link"/>
        <child link="back_right_wheel"/>
        <axis xyz="0 0 1" rpy="0 0 0"/>
        <limit effort="100" velocity="1"/>
    </joint>

    <link name="back_left_wheel">
        <inertial>
            <origin xyz="-0.08 0.0845 -0.0389" rpy="0 0 0"/>
            <mass value="0.05"/>
            <inertia ixx="1.25E-03" ixy="0" ixz="0"
                    iyy="1.25E-03" iyz="0" izz="1.0E-05"/>
        </inertial>
        <visual>
            <origin xyz="0 0 0" rpy="0 0 0"/>
            <geometry>
                <mesh filename="file://$(find x3_description)/meshes/mecanum/back_left_wheel_X3.STL"/>
            </geometry>
            <material name="">
                <color rgba="0.7 0.7 0.7 1"/>
            </material>
        </visual>
        <collision>
            <origin xyz="0 0 0" rpy="0 0 0"/>
            <geometry>
                <mesh filename="file://$(find x3_description)/meshes/mecanum/back_left_wheel_X3.STL"/>
            </geometry>
        </collision>
    </link>
    <joint name="back_left_joint" type="continuous">
        <origin xyz="-0.08 0.0845 -0.0389" rpy="1.5703 0 0"/>
        <parent link="base_link"/>
        <child link="back_left_wheel"/>
        <axis xyz="0 0 1" rpy="0 0 0"/>
        <limit effort="100" velocity="1"/>
    </joint>

    <link name="laser_link">
        <inertial>
            <origin xyz="-0.0176558922685589 0.000671805271544437 0.0219302095894866" rpy="0 0 0" />
            <mass value="0.0483909504209895" />
            <inertia ixx="1.58456966399128E-05" ixy="-4.23913983850005E-07" ixz="-2.09597897904374E-07"
                     iyy="3.89262522903605E-05" iyz="3.24809725932687E-07" izz="4.86230801106223E-05" />
        </inertial>
        <visual>
            <origin xyz="0 0 0" rpy="0 0 0"/>
            <geometry>
                <mesh filename="file://$(find x3_description)/meshes/sensor/laser_link.STL"/>
            </geometry>
            <material name="">
                <color rgba="0.7 0.7 0.7 1"/>
            </material>
        </visual>
        <collision>
            <origin xyz="0 0 0" rpy="0 0 0"/>
            <geometry>
                <mesh filename="file://$(find x3_description)/meshes/sensor/laser_link.STL"/>
            </geometry>
        </collision>
    </link>
    <joint name="laser_joint" type="fixed">
        <origin xyz="0.0435 5.25826986680105E-05 0.11" rpy="0 0 0"/>
        <parent link="base_link"/>
        <child link="laser_link"/>
    </joint>
    <link name="camera_link">
        <inertial>
            <origin xyz="0 0 0" rpy="0 0 0"/>
            <mass value="0"/>
            <inertia ixx="0" ixy="0" ixz="0" iyy="0" iyz="0" izz="0"/>
        </inertial>
        <visual>
            <origin xyz="0 0 0" rpy="0 0 0"/>
            <geometry>
                <mesh filename="file://$(find x3_description)/meshes/sensor/camera_link.STL"/>
            </geometry>
            <material name="">
                <color rgba="0.7 0.7 0.7 1"/>
            </material>
        </visual>
        <collision>
            <origin xyz="0 0 0" rpy="0 0 0"/>
            <geometry>
                <mesh filename="file://$(find x3_description)/meshes/sensor/camera_link.STL"/>
            </geometry>
        </collision>
    </link>
    <joint name="camera_joint" type="fixed">
        <origin xyz="0.057105 1.7948E-05 0.03755" rpy="0 0 0"/>
        <parent link="base_link"/>
        <child link="camera_link"/>
    </joint>

<!-- Plugins -->
    <gazebo>
		<plugin name="gazebo_ros_control" filename="libgazebo_ros_control.so">
		    <robotNamespace>/</robotNamespace>
		    <!--robotParam>robot_description</robotParam-->
		    <robotSimType>gazebo_ros_control/DefaultRobotHWSim</robotSimType>
		    <legacyModeNS>true</legacyModeNS>
		</plugin>
	</gazebo>

    <gazebo>
        <plugin name="mecanum_controller" filename="libgazebo_ros_planar_move.so">
            <robotNamespace>/</robotNamespace>
            <commandTopic>cmd_vel</commandTopic>
            <odometryTopic>odom</odometryTopic>
            <odometryFrame>odom</odometryFrame>
            <leftFrontJoint>front_left_joint</leftFrontJoint>
            <rightFrontJoint>front_right_joint</rightFrontJoint>
            <leftRearJoint>back_left_joint</leftRearJoint>
            <rightRearJoint>back_right_joint</rightRearJoint>
            <odometryRate>60.0</odometryRate>
            <robotBaseFrame>base_link</robotBaseFrame>
        </plugin>
    </gazebo>
    

    <xacro:property name="camera_name"  value  = "camera"/>
    <xacro:property name="frame_name"  value  = "camera_link"/>
    <gazebo reference="camera_link">
        <!-- arg name="camera_name"  default  = "mycamera"/ -->
    <sensor name="abzg_camera" type="depth">
        <update_rate>30</update_rate>
        <camera>
            <horizontal_fov>1.047198</horizontal_fov>
            <image>
                <width>640</width>
                <height>480</height>
                <format>R8G8B8</format>
            </image>
            <clip>
                <near>0.05</near>
                <far>3</far>
            </clip>
        </camera>
        <plugin name="camera_link_controller" filename="libgazebo_ros_openni_kinect.so">
            <baseline>0.2</baseline>
            <alwaysOn>true</alwaysOn>
            <updateRate>1.0</updateRate>
            <cameraName>${camera_name}_ir</cameraName>
            <imageTopicName>/${camera_name}/color/image_raw</imageTopicName>
            <cameraInfoTopicName>/${camera_name}/color/camera_info</cameraInfoTopicName>
            <depthImageTopicName>/${camera_name}/depth/image_raw</depthImageTopicName>
            <depthImageInfoTopicName>/${camera_name}/depth/camera_info</depthImageInfoTopicName>
            <pointCloudTopicName>/${camera_name}/depth/points</pointCloudTopicName>
            <frameName>${frame_name}</frameName>
            <pointCloudCutoff>0.5</pointCloudCutoff>
            <pointCloudCutoffMax>3.0</pointCloudCutoffMax>
            <distortionK1>0.00000001</distortionK1>
            <distortionK2>0.00000001</distortionK2>
            <distortionK3>0.00000001</distortionK3>
            <distortionT1>0.00000001</distortionT1>
            <distortionT2>0.00000001</distortionT2>
            <CxPrime>0</CxPrime>
            <Cx>0</Cx>
            <Cy>0</Cy>
            <focalLength>0</focalLength>
            <hackBaseline>0</hackBaseline>
        </plugin>
    </sensor>
    </gazebo>


    <gazebo reference="laser_link">
        <sensor type="ray" name="head_hokuyo_sensor">
            <pose>0 0 0 0 0 0</pose>
            <visualize>false</visualize>
            <update_rate>40</update_rate>
            <ray>
                <scan>
                    <horizontal>
                        <samples>720</samples>
                        <resolution>1</resolution>
                        <min_angle>-1.570796</min_angle>
                        <max_angle>1.570796</max_angle>
                    </horizontal>
                </scan>
                <range>
                    <min>0.10</min>
                    <max>30.0</max>
                    <resolution>0.01</resolution>
                </range>
                <noise>
                    <type>gaussian</type>
                    <!-- Noise parameters based on published spec for Hokuyo laser
                    achieving "+-30mm" accuracy at range < 10m.  A mean of 0.0m and
                    stddev of 0.01m will put 99.7% of samples within 0.03m of the true
                    reading. -->
                    <mean>0.0</mean>
                    <stddev>0.01</stddev>
                </noise>
            </ray>
            <plugin name="gazebo_ros_head_hokuyo_controller" filename="libgazebo_ros_laser.so">
                <topicName>/scan</topicName>
                <frameName>laser_link</frameName>
            </plugin>
        </sensor>
    </gazebo>

    
    <gazebo reference="imu_link">
        <gravity>true</gravity>
        <sensor name="imu_sensor" type="imu">
            <always_on>true</always_on>
            <update_rate>100</update_rate>
            <visualize>true</visualize>
            <topic>/imu/imu_data</topic>
            <plugin filename="libgazebo_ros_imu_sensor.so" name="imu_plugin">
                <topicName>/imu/imu_data</topicName>
                <bodyName>imu_link</bodyName>
                <updateRateHZ>100.0</updateRateHZ>
                <gaussianNoise>0.0</gaussianNoise>
                <xyzOffset>0 0 0</xyzOffset>
                <rpyOffset>0 0 0</rpyOffset>
                <frameName>imu_link</frameName>
            </plugin>
            <pose>0 0 0 0 0 0</pose>
        </sensor>
    </gazebo>


    <!-- Colors -->

     <gazebo reference="back_left_wheel">
        <mu1 value="1.0"/>
        <mu2 value="1.0"/>
        <kp value="1000000.0" />
        <kd value="10.0" />
        <fdir1 value="1 0 0"/>  <!-- Rolling direction -->
        <material>Gazebo/Black</material>
    </gazebo>

    <gazebo reference="back_right_wheel">
        <mu1 value="1.0"/>
        <mu2 value="1.0"/>
        <kp value="1000000.0" />
        <kd value="10.0" />
        <fdir1 value="1 0 0"/>  <!-- Rolling direction -->
        <material>Gazebo/Black</material>
    </gazebo>

    <gazebo reference="front_left_wheel">
        <mu1 value="1.0"/>
        <mu2 value="1.0"/>
        <kp value="1000000.0" />
        <kd value="10.0" />
        <fdir1 value="1 0 0"/>  <!-- Rolling direction -->
        <material>Gazebo/Black</material>
    </gazebo>

    <gazebo reference="front_right_wheel">
        <mu1 value="1.0"/>
        <mu2 value="1.0"/>
        <kp value="1000000.0" />
        <kd value="10.0" />
        <fdir1 value="1 0 0"/>  <!-- Rolling direction -->
        <material>Gazebo/Black</material>
    </gazebo>   

    <gazebo reference="base_link">
        <material>Gazebo/Green</material>
    </gazebo>

    <gazebo reference="camera_link">
        <material>Gazebo/White</material>
    </gazebo>

    <gazebo reference="laser_link">
        <material>Gazebo/White</material>
    </gazebo>

    <gazebo reference="imu_link">
        <material>Gazebo/Black</material>
    </gazebo>


</robot>
